2017-06-17 18:03:39
Traceback (most recent call last):
  File "/Users/wbond/Library/Application Support/Sublime Text 3/Packages/SFTP/sftp/proc.py", line 186, in read
OSError: [Errno 9] Bad file descriptor

During handling of the above exception, another exception occurred:

Traceback (most recent call last):
  File "/Users/wbond/Library/Application Support/Sublime Text 3/Packages/SFTP/sftp/threads.py", line 16, in run_with_except_hook
  File "/Users/wbond/Library/Application Support/Sublime Text 3/Packages/SFTP/sftp/file_transfer.py", line 68, in run
  File "/Users/wbond/Library/Application Support/Sublime Text 3/Packages/SFTP/sftp/file_transfer.py", line 206, in clone
  File "/Users/wbond/Library/Application Support/Sublime Text 3/Packages/SFTP/sftp/sftp_transport.py", line 302, in connect
  File "/Users/wbond/Library/Application Support/Sublime Text 3/Packages/SFTP/sftp/sftp_transport.py", line 135, in connect
  File "/Users/wbond/Library/Application Support/Sublime Text 3/Packages/SFTP/sftp/proc.py", line 211, in read
ChildProcessError: [Errno 10] No child processes
